#VRML_SIM R2021a utf8
WorldInfo {
  coordinateSystem "NUE"
}
Viewpoint {
  orientation -0.7536659073333992 0.6301544766791046 0.18679677632284752 0.7153792004452659
  position 1.22248025731606 1.9089777702742614 2.2291582958141616
}
TexturedBackground {
}
TexturedBackgroundLight {
}
RectangleArena {
}
IprHd6m180 {
}
Robot {
  translation 0 0.5 0
  scale 0.01 0.01 0.01
  children [
    HingeJoint {
      jointParameters HingeJointParameters {
      }
      device [
        RotationalMotor {
          muscles [
            Muscle {
            }
          ]
        }
      ]
    }
    DEF hand Shape {
      appearance PBRAppearance {
        baseColorMap ImageTexture {
          url [
            "textures/plastic.jpg"
          ]
        }
        roughness 1
        metalness 0
      }
      geometry Mesh {
        url [
          "/home/minseok/D/Uni/10/Masterarbeit/Main/World/hand/Hand/Hand.obj"
        ]
      }
    }
  ]
  boundingObject Mesh {
    url [
      "/home/minseok/D/Uni/10/Masterarbeit/Main/World/hand/Hand/Hand.obj"
    ]
  }
  physics Physics {
    mass 10
  }
}
Youbot {
  hidden translation_9 0.228 -0.158 -0.055
  hidden translation_10 0.228 0.158 -0.055
  hidden translation_11 -0.228 -0.158 -0.055
  hidden translation_12 -0.228 0.158 -0.055
  translation 0.5 0.1 0
}
FourWheelsRobot {
}
