#VRML_SIM R2021a utf8
WorldInfo {
  coordinateSystem "NUE"
}
Viewpoint {
  orientation 1 0 0 4.71238898038469
  position 0.4622128290565359 7.456178076291014 0.0957547783329961
}
TexturedBackground {
}
TexturedBackgroundLight {
}
DEF table Solid {
  children [
    Shape {
      appearance Appearance {
        material Material {
          diffuseColor 1 1 1
        }
      }
      geometry Box {
        size 4 0.2 2
      }
    }
  ]
  name "table"
  boundingObject Box {
    size 4 0.2 2
  }
  locked TRUE
}
DEF camera Robot {
  translation 0 2 0
  children [
    Solid {
      children [
        Shape {
          appearance PBRAppearance {
            baseColor 0.447059 0.623529 0.811765
          }
          geometry Capsule {
            height 0.1
            radius 0.05
          }
        }
        Camera {
          rotation 1 0 0 -1.57
          name "cam"
          fieldOfView 1.5
          width 128
          height 128
          antiAliasing TRUE
          recognition Recognition {
          }
        }
      ]
    }
  ]
  controller "cam"
  battery [
    0
  ]
}
DEF arm_base Solid {
  translation 1.01005 0.199961 0.5
  children [
    DEF base Shape {
      appearance Appearance {
        material Material {
          diffuseColor 0 0 0
        }
      }
      geometry Box {
        size 0.2 0.2 0.2
      }
    }
  ]
  boundingObject USE base
  physics Physics {
    mass 0.1
  }
}
DEF arm Robot {
  translation 0 1.3 0
  rotation 0.9999969003860804 0.0013540523329537495 -0.002089440238755386 -1.1596185621017814
  scale 0.003 0.003 0.003
  children [
    DEF hand Solid {
      children [
        DEF hand_shape Shape {
          appearance PBRAppearance {
            baseColor 0.913725 0.72549 0.431373
            metalness 0
          }
          geometry Mesh {
            url [
              "/home/minseok/D/Uni/10/Masterarbeit/Main/Webots/Perception/one_hand/3dmodel/one_hand/hand_v1_L1.123c38c9cfe4-2d46-434b-995c-4f7cd8b7ab01/12683_hand_v1_FINAL.obj"
            ]
          }
        }
        BallJoint {
          jointParameters BallJointParameters {
          }
          jointParameters2 JointParameters {
          }
          jointParameters3 JointParameters {
          }
          endPoint SolidReference {
            solidName "lower arm"
          }
        }
        Connector {
          name "hand_connector"
          boundingObject Sphere {
            radius 0.001
          }
          type "active"
          isLocked TRUE
          autoLock TRUE
          distanceTolerance 0.2
          axisTolerance 3.141
          rotationTolerance 3.141
          numberOfRotations 6
          snap FALSE
        }
      ]
      boundingObject USE hand_shape
    }
    DEF lower_arm Solid {
      translation 180 -2 6
      rotation 0 0 1 1.5708
      children [
        DEF lower_arm_shape Shape {
          appearance Appearance {
            material Material {
              diffuseColor 0.913725 0.72549 0.431373
            }
          }
          geometry Cylinder {
            height 300
            radius 12
          }
        }
        BallJoint {
          endPoint SolidReference {
            solidName "upper arm"
          }
        }
      ]
      name "lower arm"
      boundingObject USE lower_arm_shape
    }
    DEF upper_arm Solid {
      translation 330 -150 -110
      rotation 1 0 0 0.7854003061004253
      children [
        DEF upper_arm_shape Shape {
          appearance Appearance {
            material Material {
              diffuseColor 0.913725 0.72549 0.431373
            }
          }
          geometry Cylinder {
            height 300
            radius 12
          }
        }
      ]
      name "upper arm"
      boundingObject USE upper_arm_shape
    }
  ]
  physics Physics {
    mass 1e-06
  }
  controller "my_controller"
  supervisor TRUE
}
DEF ball Robot {
  translation 0.000149599 0.2 -0.000452398
  rotation 0.9494364148977936 5.209756189249499e-19 0.3139593828284552 0.00481579828530482
  children [
    Connector {
      type "passive"
      autoLock TRUE
      distanceTolerance 0.2
      axisTolerance 3.14
      rotationTolerance 3.14
      numberOfRotations 6
    }
    Solid {
      translation 0.0031616734373574548 0.12825434979980027 -0.009561134521284494
      rotation -0.1201799016173378 0.9894008247019193 -0.08150337003099246 1.6866355731805152
      children [
        DEF ball Shape {
          appearance Appearance {
            material Material {
              diffuseColor 0.937255 0.160784 0.160784
            }
          }
          geometry Sphere {
            radius 0.03
          }
        }
      ]
      boundingObject USE ball
      physics Physics {
      }
    }
  ]
  name "ball1"
  boundingObject USE ball
  physics Physics {
    mass 10
  }
  controller "passive_obj"
}
DEF STILL_WATER Fluid {
  translation 3 -1 0
  children [
    DEF S Shape {
      appearance DEF WATER_APPEARANCE PBRAppearance {
        baseColor 0 0.501961 1
        transparency 0.5
        roughness 1.1102230246251565e-16
        metalness 0
      }
      geometry Box {
        size 1 1 1
      }
    }
  ]
  name "swimming pool"
  boundingObject USE S
}
DEF TETRAHEDRON_SOLID Solid {
  translation 3 -1 0
  rotation 0.07022487422654634 0.9959673769797767 0.055834138588229526 -1.3036678439191811
  scale 2 2 2
  children [
    DEF TETRAHEDRON Shape {
      appearance DEF DARK_BROWN PBRAppearance {
        baseColor 0.501961 0.337255 0.2
        roughness 1.1102230246251565e-16
        metalness 0
      }
      geometry IndexedFaceSet {
        coord Coordinate {
          point [
            0 0 -0.1
            -0.1 0 0.1
            0.1 0 0.1
            0 0.1 0
          ]
        }
        coordIndex [
          0, 2, 1, -1, 0, 3, 2, -1, 1, 2
          3, -1, 0, 1, 3, -1
        ]
      }
    }
  ]
  name "tethrahedron"
  immersionProperties [
    DEF SWIMMING_POOL_IMMERSION_PROPERTIES ImmersionProperties {
      fluidName "swimming pool"
      dragForceCoefficients 0.1 0 0
      dragTorqueCoefficients 0.001 0 0
      viscousResistanceTorqueCoefficient 0.005
    }
  ]
  boundingObject USE TETRAHEDRON
  physics Physics {
    density 400
    damping Damping {
      linear 0.5
      angular 0.5
    }
  }
}
