#VRML_SIM R2021a utf8
WorldInfo {
  coordinateSystem "NUE"
}
Viewpoint {
  orientation 0 1 0 0
  position 0.358433428063562 0.6430025777137713 5.260649782108867
}
TexturedBackground {
}
TexturedBackgroundLight {
}
DEF table Solid {
  children [
    Shape {
      appearance Appearance {
        material Material {
          diffuseColor 1 1 1
        }
      }
      geometry Box {
        size 4 0.2 2
      }
    }
  ]
  name "table"
  boundingObject Box {
    size 4 0.2 2
  }
  locked TRUE
}
DEF camera Robot {
  translation 0 2 0
  children [
    Solid {
      children [
        Shape {
          appearance PBRAppearance {
            baseColor 0.447059 0.623529 0.811765
          }
          geometry Capsule {
            height 0.1
            radius 0.05
          }
        }
        Camera {
          rotation 1 0 0 -1.57
          name "cam"
          fieldOfView 1.5
          width 128
          height 128
          antiAliasing TRUE
          recognition Recognition {
          }
        }
      ]
    }
  ]
  controller "cam"
  battery [
    0
  ]
}
DEF arm Robot {
  children [
    DEF upper_arm Solid {
      translation 1.5 0.4999843040000001 0
      children [
        DEF ua_la BallJoint {
          jointParameters DEF j1 BallJointParameters {
          }
          jointParameters2 JointParameters {
          }
          jointParameters3 JointParameters {
          }
          endPoint DEF lower_arm Solid {
            translation -0.5499992686372157 0.5000008044978805 0
            rotation 0 0 1 1.5707985372756086
            children [
              BallJoint {
                jointParameters BallJointParameters {
                }
                jointParameters2 JointParameters {
                }
                jointParameters3 JointParameters {
                }
                endPoint DEF hand Solid {
                  translation -8.531327780310323e-07 0.5999999999993936 0
                  rotation -0.2849888001794463 0.6412235720760928 -0.7124701498212086 1.570798680846595
                  scale 0.003 0.003 0.003
                  children [
                    DEF hand_shape Shape {
                      appearance PBRAppearance {
                        baseColor 0.913725 0.72549 0.431373
                        metalness 0
                      }
                      geometry Mesh {
                        url [
                          "/home/minseok/D/Uni/10/Masterarbeit/Main/Webots/Perception/one_hand/3dmodel/one_hand/hand_v1_L1.123c38c9cfe4-2d46-434b-995c-4f7cd8b7ab01/12683_hand_v1_FINAL.obj"
                        ]
                      }
                    }
                    DEF hand_connector Connector {
                      name "hand_connector"
                      boundingObject Sphere {
                        radius 0.001
                      }
                      type "active"
                      isLocked TRUE
                      autoLock TRUE
                      distanceTolerance 0.2
                      axisTolerance 3.141
                      rotationTolerance 3.141
                      numberOfRotations 6
                      snap FALSE
                    }
                  ]
                  physics Physics {
                    density -1
                    mass 1
                  }
                }
              }
              DEF lower_arm_shape Shape {
                appearance Appearance {
                  material Material {
                    diffuseColor 0.913725 0.72549 0.431373
                  }
                }
                geometry Cylinder {
                  height 1
                  radius 0.05
                }
              }
            ]
            name "lower arm"
            boundingObject USE lower_arm_shape
            physics Physics {
              density -1
              mass 1
            }
          }
        }
        DEF upper_arm_shape Shape {
          appearance Appearance {
            material Material {
              diffuseColor 0.913725 0.72549 0.431373
            }
          }
          geometry Cylinder {
            height 1
            radius 0.05
          }
        }
      ]
      name "upper arm"
      boundingObject USE upper_arm_shape
      physics Physics {
        density -1
        mass 1
      }
      locked TRUE
    }
  ]
  name "robot(1)"
  controller "my_controller"
  supervisor TRUE
}
DEF deprecated Robot {
  translation 0 -40810.057952000934 0
  rotation 0.9999969003860802 0.0013540523329537498 -0.0020894402387553854 -1.1596185621017814
  scale 0.003 0.003 0.003
  physics Physics {
    mass 1e-06
  }
  controller "my_controller"
  supervisor TRUE
}
DEF ball Robot {
  translation 0.005877212182565766 0.11414527163819362 -0.01777634110110836
  rotation 0.9494643526988232 -2.4914205847791658e-05 0.31387488324726925 -1.3715167160470978
  children [
    Connector {
      type "passive"
      autoLock TRUE
      distanceTolerance 0.2
      axisTolerance 3.14
      rotationTolerance 3.14
      numberOfRotations 6
    }
    Solid {
      translation 0.0031616734373574548 0.12825434979980027 -0.009561134521284494
      rotation -0.1201799016173378 0.9894008247019193 -0.08150337003099246 1.6866355731805152
      children [
        DEF ball Shape {
          appearance Appearance {
            material Material {
              diffuseColor 0.937255 0.160784 0.160784
            }
          }
          geometry Sphere {
            radius 0.03
          }
        }
      ]
      boundingObject USE ball
      physics Physics {
      }
    }
  ]
  name "ball1"
  boundingObject USE ball
  physics Physics {
    mass 10
  }
  controller "passive_obj"
}
DEF STILL_WATER Fluid {
  translation 3 -1 0
  children [
    DEF S Shape {
      appearance DEF WATER_APPEARANCE PBRAppearance {
        baseColor 0 0.501961 1
        transparency 0.5
        roughness 1.1102230246251565e-16
        metalness 0
      }
      geometry Box {
        size 1 1 1
      }
    }
  ]
  name "swimming pool"
  boundingObject USE S
}
DEF TETRAHEDRON_SOLID Solid {
  translation 3.001104739638007 -0.5367459661538119 -0.00018078833929558932
  rotation 0.05812829493801482 0.9973312607406366 0.0441753061912573 -1.3022685835551655
  scale 2 2 2
  children [
    DEF TETRAHEDRON Shape {
      appearance DEF DARK_BROWN PBRAppearance {
        baseColor 0.501961 0.337255 0.2
        roughness 1.1102230246251565e-16
        metalness 0
      }
      geometry IndexedFaceSet {
        coord Coordinate {
          point [
            0 0 -0.1
            -0.1 0 0.1
            0.1 0 0.1
            0 0.1 0
          ]
        }
        coordIndex [
          0, 2, 1, -1, 0, 3, 2, -1, 1, 2
          3, -1, 0, 1, 3, -1
        ]
      }
    }
  ]
  name "tethrahedron"
  immersionProperties [
    DEF SWIMMING_POOL_IMMERSION_PROPERTIES ImmersionProperties {
      fluidName "swimming pool"
      dragForceCoefficients 0.1 0 0
      dragTorqueCoefficients 0.001 0 0
      viscousResistanceTorqueCoefficient 0.005
    }
  ]
  boundingObject USE TETRAHEDRON
  physics Physics {
    density 400
    damping Damping {
      linear 0.5
      angular 0.5
    }
  }
}
